Traceback (most recent call last):
  File "c:\Users\bmurr\CHE 498\pyomo_jupyter_book\.venv\Lib\site-packages\jupyter_cache\executors\utils.py", line 58, in single_nb_execution
    executenb(
  File "c:\Users\bmurr\CHE 498\pyomo_jupyter_book\.venv\Lib\site-packages\nbclient\client.py", line 1314, in execute
    return NotebookClient(nb=nb, resources=resources, km=km, **kwargs).execute()
           ^^^^^^^^^^^^^^^^^^^^^^^^^^^^^^^^^^^^^^^^^^^^^^^^^^^^^^^^^^^^^^^^^^^^^
  File "c:\Users\bmurr\CHE 498\pyomo_jupyter_book\.venv\Lib\site-packages\jupyter_core\utils\__init__.py", line 165, in wrapped
    return loop.run_until_complete(inner)
           ^^^^^^^^^^^^^^^^^^^^^^^^^^^^^^
  File "C:\Users\bmurr\AppData\Local\Programs\Python\Python311\Lib\asyncio\base_events.py", line 653, in run_until_complete
    return future.result()
           ^^^^^^^^^^^^^^^
  File "c:\Users\bmurr\CHE 498\pyomo_jupyter_book\.venv\Lib\site-packages\nbclient\client.py", line 709, in async_execute
    await self.async_execute_cell(
  File "c:\Users\bmurr\CHE 498\pyomo_jupyter_book\.venv\Lib\site-packages\nbclient\client.py", line 1062, in async_execute_cell
    await self._check_raise_for_error(cell, cell_index, exec_reply)
  File "c:\Users\bmurr\CHE 498\pyomo_jupyter_book\.venv\Lib\site-packages\nbclient\client.py", line 918, in _check_raise_for_error
    raise CellExecutionError.from_cell_and_msg(cell, exec_reply_content)
nbclient.exceptions.CellExecutionError: An error occurred while executing the following cell:
------------------
import pyomo.environ as pyo

numpoints = 5
model = m = pyo.ConcreteModel()
m.points = pyo.RangeSet(0,numpoints-1)
m.h = pyo.Param(initialize=1.0/(numpoints-1))

m.z = pyo.Var(m.points)
m.dzdt = pyo.Var(m.points)

m.obj = pyo.Objective(expr=1) # Dummy Objective

def _zdot(m, i):
    return m.dzdt[i] == m.z[i]**2 - 2*m.z[i] +1
m.zdot = pyo.Constraint(m.points,rule=_zdot)

def _back_diff(m,i):
    if i == 0:
        return pyo.Constraint.Skip
    return m.dzdt[i] == (m.z[i]-m.z[i-1])/m.h
m.back_diff = pyo.Constraint(m.points,rule=_back_diff)

def _init_con(m):
    return m.z[0] == -3
m.init_con = pyo.Constraint(rule=_init_con)

ipopt_runner_path = "/home/runner/work/pyomo_jupyter_book/pyomo_jupyter_book/solvers/ipopt"
solver = pyo.SolverFactory('ipopt', executable=ipopt_runner_path)
solver.solve(m,tee=True)

import matplotlib.pyplot as plt

analytical_t = [0.01*i for i in range(0,101)]
analytical_z = [(4*t-3)/(4*t+1) for t in analytical_t]

findiff_t = [m.h*i for i in m.points]
findiff_z = [pyo.value(m.z[i]) for i in m.points]

plt.plot(analytical_t,analytical_z,'b',label='analytical solution')
plt.plot(findiff_t,findiff_z,'ro--',label='finite difference solution')
plt.legend(loc='best')
plt.xlabel('t')
plt.show()

------------------


[1;31m---------------------------------------------------------------------------[0m
[1;31mModuleNotFoundError[0m                       Traceback (most recent call last)
Cell [1;32mIn[1], line 1[0m
[1;32m----> 1[0m [38;5;28;01mimport[39;00m [38;5;21;01mpyomo[39;00m[38;5;21;01m.[39;00m[38;5;21;01menviron[39;00m [38;5;28;01mas[39;00m [38;5;21;01mpyo[39;00m
[0;32m      3[0m numpoints [38;5;241m=[39m [38;5;241m5[39m
[0;32m      4[0m model [38;5;241m=[39m m [38;5;241m=[39m pyo[38;5;241m.[39mConcreteModel()

[1;31mModuleNotFoundError[0m: No module named 'pyomo'

