Traceback (most recent call last):
  File "/home/murraybj/CHE498/pyomo_jupyter_book/.venv/lib/python3.10/site-packages/jupyter_cache/executors/utils.py", line 58, in single_nb_execution
    executenb(
  File "/home/murraybj/CHE498/pyomo_jupyter_book/.venv/lib/python3.10/site-packages/nbclient/client.py", line 1314, in execute
    return NotebookClient(nb=nb, resources=resources, km=km, **kwargs).execute()
  File "/home/murraybj/CHE498/pyomo_jupyter_book/.venv/lib/python3.10/site-packages/jupyter_core/utils/__init__.py", line 165, in wrapped
    return loop.run_until_complete(inner)
  File "/usr/lib/python3.10/asyncio/base_events.py", line 649, in run_until_complete
    return future.result()
  File "/home/murraybj/CHE498/pyomo_jupyter_book/.venv/lib/python3.10/site-packages/nbclient/client.py", line 709, in async_execute
    await self.async_execute_cell(
  File "/home/murraybj/CHE498/pyomo_jupyter_book/.venv/lib/python3.10/site-packages/nbclient/client.py", line 1062, in async_execute_cell
    await self._check_raise_for_error(cell, cell_index, exec_reply)
  File "/home/murraybj/CHE498/pyomo_jupyter_book/.venv/lib/python3.10/site-packages/nbclient/client.py", line 918, in _check_raise_for_error
    raise CellExecutionError.from_cell_and_msg(cell, exec_reply_content)
nbclient.exceptions.CellExecutionError: An error occurred while executing the following cell:
------------------
import pyomo.environ as pyo
from pyomo.dae import ContinuousSet, DerivativeVar

a_conc = {0.1:0.606, 0.2:0.368, 0.3:0.223, 0.4:0.135, 0.5:0.082,
          0.6:0.05, 0.7:0.03, 0.8:0.018, 0.9:0.011, 1.0:0.007}

b_conc = {0.1:0.373, 0.2:0.564, 0.3:0.647, 0.4:0.669, 0.5:0.656,
          0.6:0.624, 0.7:0.583, 0.8:0.539, 0.9:0.494, 1.0:0.451}

m = pyo.ConcreteModel()

m.meas_time = pyo.Set(initialize=sorted(a_conc.keys()),ordered=True)
m.ameas = pyo.Param(m.meas_time, initialize=a_conc)
m.bmeas = pyo.Param(m.meas_time, initialize=b_conc)

m.time = ContinuousSet(initialize=m.meas_time, bounds=(0,1))

m.a = pyo.Var(m.time, bounds=(0,1))
m.b = pyo.Var(m.time, bounds=(0,1))

m.dadt = DerivativeVar(m.a)
m.dbdt = DerivativeVar(m.b)

m.k1 = pyo.Var()
m.k2 = pyo.Var()

def _a_diffeq(m,t):
    return m.dadt[t] == -m.k1*m.a[t]
m.a_diffeq = pyo.Constraint(m.time, rule=_a_diffeq)

def _b_diffeq(m,t):
    return m.dbdt[t] == m.k1*m.a[t] - m.k2*m.b[t]
m.b_diffeq = pyo.Constraint(m.time, rule=_b_diffeq)

m.ainit = pyo.Constraint(expr=m.a[0]==1)
m.binit = pyo.Constraint(expr=m.b[0]==0)

def _obj(m):
    return sum((m.a[t]-m.ameas[t])**2+(m.b[t]-m.bmeas[t])**2 for t in m.meas_time)
m.obj = pyo.Objective(rule=_obj)

discretizer = pyo.TransformationFactory('dae.collocation')
discretizer.apply_to(m,nfe=10,ncp=3,scheme='LAGRANGE-RADAU')

ipopt_runner_path = "/home/runner/work/pyomo_jupyter_book/pyomo_jupyter_book/solvers/ipopt"
solver = pyo.SolverFactory('ipopt', executable=ipopt_runner_path)
solver.solve(m, tee=True)

print('k1= '+str(pyo.value(m.k1)))
print('k2= '+str(pyo.value(m.k2)))

meas_time = list(m.meas_time)
a_meas = [pyo.value(m.ameas[i]) for i in m.meas_time]
b_meas = [pyo.value(m.bmeas[i]) for i in m.meas_time]

t = list(m.time)
a = [pyo.value(m.a[i]) for i in m.time]
b = [pyo.value(m.b[i]) for i in m.time]
    
import matplotlib.pyplot as plt

plt.plot(t,a,label='A')
plt.plot(t,b,label='B')
plt.plot(meas_time,a_meas,'o')
plt.plot(meas_time,b_meas,'o')
plt.legend(loc='best')
plt.xlabel('t')
plt.ylabel('concentration')
plt.title('Kinetic Parameter Estimation')
plt.show()

------------------

----- stdout -----
WARNING: Failed to create solver with name 'ipopt': Failed to set executable
for solver ipopt. File with
name=/home/runner/work/pyomo_jupyter_book/pyomo_jupyter_book/solvers/ipopt
either does not exist or it is not executable. To skip this validation, call
set_executable with validate=False.
Traceback (most recent call last):
  File "/home/murraybj/CHE498/pyomo_jupyter_book/.venv/lib/python3.10/site-packages/pyomo/opt/base/solvers.py", line 148, in __call__
    opt = self._cls[_name](**kwds)
  File "/home/murraybj/CHE498/pyomo_jupyter_book/.venv/lib/python3.10/site-packages/pyomo/solvers/plugins/solvers/IPOPT.py", line 44, in __init__
    super(IPOPT, self).__init__(**kwds)
  File "/home/murraybj/CHE498/pyomo_jupyter_book/.venv/lib/python3.10/site-packages/pyomo/opt/solver/shellcmd.py", line 66, in __init__
    self.set_executable(name=executable, validate=validate)
  File "/home/murraybj/CHE498/pyomo_jupyter_book/.venv/lib/python3.10/site-packages/pyomo/opt/solver/shellcmd.py", line 115, in set_executable
    raise ValueError(
ValueError: Failed to set executable for solver ipopt. File with name=/home/runner/work/pyomo_jupyter_book/pyomo_jupyter_book/solvers/ipopt either does not exist or it is not executable. To skip this validation, call set_executable with validate=False.
------------------

[0;31m---------------------------------------------------------------------------[0m
[0;31mRuntimeError[0m                              Traceback (most recent call last)
Cell [0;32mIn[3], line 47[0m
[1;32m     45[0m ipopt_runner_path [38;5;241m=[39m [38;5;124m"[39m[38;5;124m/home/runner/work/pyomo_jupyter_book/pyomo_jupyter_book/solvers/ipopt[39m[38;5;124m"[39m
[1;32m     46[0m solver [38;5;241m=[39m pyo[38;5;241m.[39mSolverFactory([38;5;124m'[39m[38;5;124mipopt[39m[38;5;124m'[39m, executable[38;5;241m=[39mipopt_runner_path)
[0;32m---> 47[0m [43msolver[49m[38;5;241;43m.[39;49m[43msolve[49m[43m([49m[43mm[49m[43m,[49m[43m [49m[43mtee[49m[38;5;241;43m=[39;49m[38;5;28;43;01mTrue[39;49;00m[43m)[49m
[1;32m     49[0m [38;5;28mprint[39m([38;5;124m'[39m[38;5;124mk1= [39m[38;5;124m'[39m[38;5;241m+[39m[38;5;28mstr[39m(pyo[38;5;241m.[39mvalue(m[38;5;241m.[39mk1)))
[1;32m     50[0m [38;5;28mprint[39m([38;5;124m'[39m[38;5;124mk2= [39m[38;5;124m'[39m[38;5;241m+[39m[38;5;28mstr[39m(pyo[38;5;241m.[39mvalue(m[38;5;241m.[39mk2)))

File [0;32m~/CHE498/pyomo_jupyter_book/.venv/lib/python3.10/site-packages/pyomo/opt/base/solvers.py:99[0m, in [0;36mUnknownSolver.solve[0;34m(self, *args, **kwds)[0m
[1;32m     97[0m [38;5;28;01mdef[39;00m [38;5;21msolve[39m([38;5;28mself[39m, [38;5;241m*[39margs, [38;5;241m*[39m[38;5;241m*[39mkwds):
[1;32m     98[0m [38;5;250m    [39m[38;5;124;03m"""Perform optimization and return an SolverResults object."""[39;00m
[0;32m---> 99[0m     [38;5;28;43mself[39;49m[38;5;241;43m.[39;49m[43m_solver_error[49m[43m([49m[38;5;124;43m'[39;49m[38;5;124;43msolve[39;49m[38;5;124;43m'[39;49m[43m)[49m

File [0;32m~/CHE498/pyomo_jupyter_book/.venv/lib/python3.10/site-packages/pyomo/opt/base/solvers.py:116[0m, in [0;36mUnknownSolver._solver_error[0;34m(self, method_name)[0m
[1;32m    115[0m     [38;5;28;01mdef[39;00m [38;5;21m_solver_error[39m([38;5;28mself[39m, method_name):
[0;32m--> 116[0m         [38;5;28;01mraise[39;00m [38;5;167;01mRuntimeError[39;00m(
[1;32m    117[0m [38;5;250m            [39m[38;5;124;03m"""Attempting to use an unavailable solver.[39;00m
[1;32m    118[0m 
[1;32m    119[0m [38;5;124;03mThe SolverFactory was unable to create the solver "%s"[39;00m
[1;32m    120[0m [38;5;124;03mand returned an UnknownSolver object.  This error is raised at the point[39;00m
[1;32m    121[0m [38;5;124;03mwhere the UnknownSolver object was used as if it were valid (by calling[39;00m
[1;32m    122[0m [38;5;124;03mmethod "%s").[39;00m
[1;32m    123[0m 
[1;32m    124[0m [38;5;124;03mThe original solver was created with the following parameters:[39;00m
[1;32m    125[0m [38;5;124;03m\t"""[39;00m
[1;32m    126[0m             [38;5;241m%[39m ([38;5;28mself[39m[38;5;241m.[39mtype, method_name)
[1;32m    127[0m             [38;5;241m+[39m [38;5;124m"[39m[38;5;130;01m\n[39;00m[38;5;130;01m\t[39;00m[38;5;124m"[39m[38;5;241m.[39mjoin([38;5;124m"[39m[38;5;132;01m%s[39;00m[38;5;124m: [39m[38;5;132;01m%s[39;00m[38;5;124m"[39m [38;5;241m%[39m i [38;5;28;01mfor[39;00m i [38;5;129;01min[39;00m [38;5;28msorted[39m([38;5;28mself[39m[38;5;241m.[39m_kwds[38;5;241m.[39mitems()))
[1;32m    128[0m             [38;5;241m+[39m [38;5;124m"[39m[38;5;130;01m\n[39;00m[38;5;130;01m\t[39;00m[38;5;124m_args: [39m[38;5;132;01m%s[39;00m[38;5;124m"[39m [38;5;241m%[39m ([38;5;28mself[39m[38;5;241m.[39m_args,)
[1;32m    129[0m             [38;5;241m+[39m [38;5;124m"[39m[38;5;130;01m\n[39;00m[38;5;130;01m\t[39;00m[38;5;124moptions: [39m[38;5;132;01m%s[39;00m[38;5;124m"[39m [38;5;241m%[39m ([38;5;28mself[39m[38;5;241m.[39moptions,)
[1;32m    130[0m         )

[0;31mRuntimeError[0m: Attempting to use an unavailable solver.

The SolverFactory was unable to create the solver "ipopt"
and returned an UnknownSolver object.  This error is raised at the point
where the UnknownSolver object was used as if it were valid (by calling
method "solve").

The original solver was created with the following parameters:
	executable: /home/runner/work/pyomo_jupyter_book/pyomo_jupyter_book/solvers/ipopt
	type: ipopt
	_args: ()
	options: {}

