Traceback (most recent call last):
  File "/home/runner/.local/lib/python3.12/site-packages/jupyter_core/utils/__init__.py", line 154, in wrapped
    asyncio.get_running_loop()
RuntimeError: no running event loop

During handling of the above exception, another exception occurred:

Traceback (most recent call last):
  File "/home/runner/.local/lib/python3.12/site-packages/jupyter_cache/executors/utils.py", line 58, in single_nb_execution
    executenb(
  File "/home/runner/.local/lib/python3.12/site-packages/nbclient/client.py", line 1319, in execute
    return NotebookClient(nb=nb, resources=resources, km=km, **kwargs).execute()
           ^^^^^^^^^^^^^^^^^^^^^^^^^^^^^^^^^^^^^^^^^^^^^^^^^^^^^^^^^^^^^^^^^^^^^
  File "/home/runner/.local/lib/python3.12/site-packages/jupyter_core/utils/__init__.py", line 158, in wrapped
    return loop.run_until_complete(inner)
           ^^^^^^^^^^^^^^^^^^^^^^^^^^^^^^
  File "/usr/lib/python3.12/asyncio/base_events.py", line 687, in run_until_complete
    return future.result()
           ^^^^^^^^^^^^^^^
  File "/home/runner/.local/lib/python3.12/site-packages/nbclient/client.py", line 709, in async_execute
    await self.async_execute_cell(
  File "/home/runner/.local/lib/python3.12/site-packages/nbclient/client.py", line 1062, in async_execute_cell
    await self._check_raise_for_error(cell, cell_index, exec_reply)
  File "/home/runner/.local/lib/python3.12/site-packages/nbclient/client.py", line 918, in _check_raise_for_error
    raise CellExecutionError.from_cell_and_msg(cell, exec_reply_content)
nbclient.exceptions.CellExecutionError: An error occurred while executing the following cell:
------------------
import pyomo.environ as pyo

A = ['hammer', 'wrench', 'screwdriver', 'towel']
b = {'hammer':8, 'wrench':3, 'screwdriver':6, 'towel':11}
w = {'hammer':5, 'wrench':7, 'screwdriver':4, 'towel':3}
W_max = 14

model = pyo.ConcreteModel()
model.x = pyo.Var( A, within=pyo.Binary )

model.obj = pyo.Objective(
    expr = sum( b[i]*model.x[i] for i in A ), 
    sense = pyo.maximize )

model.weight_con = pyo.Constraint(
    expr = sum( w[i]*model.x[i] for i in A ) <= W_max )

opt = pyo.SolverFactory('cbc')
opt_success = opt.solve(model)

total_weight = sum( w[i]*pyo.value(model.x[i]) for i in A )
print('Total Weight:', total_weight)
print('Total Benefit:', pyo.value(model.obj))

print('%12s %12s' % ('Item', 'Selected'))
print('=========================')
for i in A:
    acquired = 'No'
    if pyo.value(model.x[i]) >= 0.5:
        acquired = 'Yes'
    print('%12s %12s' % (i, acquired))
print('-------------------------')

------------------

----- stdout -----
WARNING: Could not locate the 'cbc' executable, which is required for solver
cbc
------------------

[31m---------------------------------------------------------------------------[39m
[31mApplicationError[39m                          Traceback (most recent call last)
[36mCell[39m[36m [39m[32mIn[1][39m[32m, line 19[39m
[32m     15[39m model.weight_con = pyo.Constraint(
[32m     16[39m     expr = [38;5;28msum[39m( w[i]*model.x[i] [38;5;28;01mfor[39;00m i [38;5;129;01min[39;00m A ) <= W_max )
[32m     18[39m opt = pyo.SolverFactory([33m'[39m[33mcbc[39m[33m'[39m)
[32m---> [39m[32m19[39m opt_success = [43mopt[49m[43m.[49m[43msolve[49m[43m([49m[43mmodel[49m[43m)[49m
[32m     21[39m total_weight = [38;5;28msum[39m( w[i]*pyo.value(model.x[i]) [38;5;28;01mfor[39;00m i [38;5;129;01min[39;00m A )
[32m     22[39m [38;5;28mprint[39m([33m'[39m[33mTotal Weight:[39m[33m'[39m, total_weight)

[36mFile [39m[32m~/.local/lib/python3.12/site-packages/pyomo/opt/base/solvers.py:534[39m, in [36mOptSolver.solve[39m[34m(self, *args, **kwds)[39m
[32m    531[39m [38;5;28;01mdef[39;00m [34msolve[39m([38;5;28mself[39m, *args, **kwds):
[32m    532[39m [38;5;250m    [39m[33;03m"""Solve the problem"""[39;00m
[32m--> [39m[32m534[39m     [38;5;28;43mself[39;49m[43m.[49m[43mavailable[49m[43m([49m[43mexception_flag[49m[43m=[49m[38;5;28;43;01mTrue[39;49;00m[43m)[49m
[32m    535[39m     [38;5;66;03m#[39;00m
[32m    536[39m     [38;5;66;03m# If the inputs are models, then validate that they have been[39;00m
[32m    537[39m     [38;5;66;03m# constructed! Collect suffix names to try and import from solution.[39;00m
[32m    538[39m     [38;5;66;03m#[39;00m
[32m    539[39m     [38;5;28;01mfrom[39;00m [34;01mpyomo[39;00m[34;01m.[39;00m[34;01mcore[39;00m[34;01m.[39;00m[34;01mbase[39;00m[34;01m.[39;00m[34;01mblock[39;00m [38;5;28;01mimport[39;00m BlockData

[36mFile [39m[32m~/.local/lib/python3.12/site-packages/pyomo/opt/solver/shellcmd.py:140[39m, in [36mSystemCallSolver.available[39m[34m(self, exception_flag)[39m
[32m    138[39m     [38;5;28;01mif[39;00m exception_flag:
[32m    139[39m         msg = [33m"[39m[33mNo executable found for solver [39m[33m'[39m[38;5;132;01m%s[39;00m[33m'[39m[33m"[39m
[32m--> [39m[32m140[39m         [38;5;28;01mraise[39;00m ApplicationError(msg % [38;5;28mself[39m.name)
[32m    141[39m     [38;5;28;01mreturn[39;00m [38;5;28;01mFalse[39;00m
[32m    142[39m [38;5;28;01mreturn[39;00m [38;5;28;01mTrue[39;00m

[31mApplicationError[39m: No executable found for solver 'cbc'

