Traceback (most recent call last):
  File "/home/murraybj/CHE498/pyomo_jupyter_book/.venv/lib/python3.10/site-packages/jupyter_cache/executors/utils.py", line 58, in single_nb_execution
    executenb(
  File "/home/murraybj/CHE498/pyomo_jupyter_book/.venv/lib/python3.10/site-packages/nbclient/client.py", line 1314, in execute
    return NotebookClient(nb=nb, resources=resources, km=km, **kwargs).execute()
  File "/home/murraybj/CHE498/pyomo_jupyter_book/.venv/lib/python3.10/site-packages/jupyter_core/utils/__init__.py", line 165, in wrapped
    return loop.run_until_complete(inner)
  File "/usr/lib/python3.10/asyncio/base_events.py", line 649, in run_until_complete
    return future.result()
  File "/home/murraybj/CHE498/pyomo_jupyter_book/.venv/lib/python3.10/site-packages/nbclient/client.py", line 709, in async_execute
    await self.async_execute_cell(
  File "/home/murraybj/CHE498/pyomo_jupyter_book/.venv/lib/python3.10/site-packages/nbclient/client.py", line 1062, in async_execute_cell
    await self._check_raise_for_error(cell, cell_index, exec_reply)
  File "/home/murraybj/CHE498/pyomo_jupyter_book/.venv/lib/python3.10/site-packages/nbclient/client.py", line 918, in _check_raise_for_error
    raise CellExecutionError.from_cell_and_msg(cell, exec_reply_content)
nbclient.exceptions.CellExecutionError: An error occurred while executing the following cell:
------------------
import pyomo.environ as pyo

A = ['hammer', 'wrench', 'screwdriver', 'towel']
b = {'hammer':8, 'wrench':3, 'screwdriver':6, 'towel':11}
w = {'hammer':5, 'wrench':7, 'screwdriver':4, 'towel':3}
W_max = 14
N = range(6) # create a list from 0-5

model = pyo.ConcreteModel()
model.x = pyo.Var( A )
model.q = pyo.Var( A, N, within=pyo.Binary )

def obj_rule(m):
    return sum( b[i]*m.x[i] for i in A )
model.obj = pyo.Objective(rule=obj_rule, sense = pyo.maximize )

def weight_con_rule(m):
    return sum( w[i]*m.x[i] for i in A ) <= W_max
model.weight_con = pyo.Constraint(rule=weight_con_rule)

def x_integer_rule(m, i):
    return m.x[i] == sum( j*m.q[i,j] for j in N )
model.x_integer = pyo.Constraint(A, rule=x_integer_rule)

opt = pyo.SolverFactory('glpk')
result_obj = opt.solve(model)

total_weight = sum( w[i]*pyo.value(model.x[i]) for i in A )
print('Total Weight:', total_weight)
print('Total Benefit:', pyo.value(model.obj))

print('%12s %12s' % ('Item', '# Selected'))
print('=========================')
for i in A:
    print('%12s %12s' % (i, pyo.value(model.x[i])))
print('-------------------------')
------------------

----- stdout -----
WARNING: Could not locate the 'glpsol' executable, which is required for
solver 'glpk'
------------------

[0;31m---------------------------------------------------------------------------[0m
[0;31mApplicationError[0m                          Traceback (most recent call last)
Cell [0;32mIn[1], line 26[0m
[1;32m     23[0m model[38;5;241m.[39mx_integer [38;5;241m=[39m pyo[38;5;241m.[39mConstraint(A, rule[38;5;241m=[39mx_integer_rule)
[1;32m     25[0m opt [38;5;241m=[39m pyo[38;5;241m.[39mSolverFactory([38;5;124m'[39m[38;5;124mglpk[39m[38;5;124m'[39m)
[0;32m---> 26[0m result_obj [38;5;241m=[39m [43mopt[49m[38;5;241;43m.[39;49m[43msolve[49m[43m([49m[43mmodel[49m[43m)[49m
[1;32m     28[0m total_weight [38;5;241m=[39m [38;5;28msum[39m( w[i][38;5;241m*[39mpyo[38;5;241m.[39mvalue(model[38;5;241m.[39mx[i]) [38;5;28;01mfor[39;00m i [38;5;129;01min[39;00m A )
[1;32m     29[0m [38;5;28mprint[39m([38;5;124m'[39m[38;5;124mTotal Weight:[39m[38;5;124m'[39m, total_weight)

File [0;32m~/CHE498/pyomo_jupyter_book/.venv/lib/python3.10/site-packages/pyomo/opt/base/solvers.py:534[0m, in [0;36mOptSolver.solve[0;34m(self, *args, **kwds)[0m
[1;32m    531[0m [38;5;28;01mdef[39;00m [38;5;21msolve[39m([38;5;28mself[39m, [38;5;241m*[39margs, [38;5;241m*[39m[38;5;241m*[39mkwds):
[1;32m    532[0m [38;5;250m    [39m[38;5;124;03m"""Solve the problem"""[39;00m
[0;32m--> 534[0m     [38;5;28;43mself[39;49m[38;5;241;43m.[39;49m[43mavailable[49m[43m([49m[43mexception_flag[49m[38;5;241;43m=[39;49m[38;5;28;43;01mTrue[39;49;00m[43m)[49m
[1;32m    535[0m     [38;5;66;03m#[39;00m
[1;32m    536[0m     [38;5;66;03m# If the inputs are models, then validate that they have been[39;00m
[1;32m    537[0m     [38;5;66;03m# constructed! Collect suffix names to try and import from solution.[39;00m
[1;32m    538[0m     [38;5;66;03m#[39;00m
[1;32m    539[0m     [38;5;28;01mfrom[39;00m [38;5;21;01mpyomo[39;00m[38;5;21;01m.[39;00m[38;5;21;01mcore[39;00m[38;5;21;01m.[39;00m[38;5;21;01mbase[39;00m[38;5;21;01m.[39;00m[38;5;21;01mblock[39;00m [38;5;28;01mimport[39;00m BlockData

File [0;32m~/CHE498/pyomo_jupyter_book/.venv/lib/python3.10/site-packages/pyomo/opt/solver/shellcmd.py:140[0m, in [0;36mSystemCallSolver.available[0;34m(self, exception_flag)[0m
[1;32m    138[0m     [38;5;28;01mif[39;00m exception_flag:
[1;32m    139[0m         msg [38;5;241m=[39m [38;5;124m"[39m[38;5;124mNo executable found for solver [39m[38;5;124m'[39m[38;5;132;01m%s[39;00m[38;5;124m'[39m[38;5;124m"[39m
[0;32m--> 140[0m         [38;5;28;01mraise[39;00m ApplicationError(msg [38;5;241m%[39m [38;5;28mself[39m[38;5;241m.[39mname)
[1;32m    141[0m     [38;5;28;01mreturn[39;00m [38;5;28;01mFalse[39;00m
[1;32m    142[0m [38;5;28;01mreturn[39;00m [38;5;28;01mTrue[39;00m

[0;31mApplicationError[0m: No executable found for solver 'glpk'

