Traceback (most recent call last):
  File "/home/murraybj/CHE498/pyomo_jupyter_book/.venv/lib/python3.10/site-packages/jupyter_cache/executors/utils.py", line 58, in single_nb_execution
    executenb(
  File "/home/murraybj/CHE498/pyomo_jupyter_book/.venv/lib/python3.10/site-packages/nbclient/client.py", line 1314, in execute
    return NotebookClient(nb=nb, resources=resources, km=km, **kwargs).execute()
  File "/home/murraybj/CHE498/pyomo_jupyter_book/.venv/lib/python3.10/site-packages/jupyter_core/utils/__init__.py", line 165, in wrapped
    return loop.run_until_complete(inner)
  File "/usr/lib/python3.10/asyncio/base_events.py", line 649, in run_until_complete
    return future.result()
  File "/home/murraybj/CHE498/pyomo_jupyter_book/.venv/lib/python3.10/site-packages/nbclient/client.py", line 709, in async_execute
    await self.async_execute_cell(
  File "/home/murraybj/CHE498/pyomo_jupyter_book/.venv/lib/python3.10/site-packages/nbclient/client.py", line 1062, in async_execute_cell
    await self._check_raise_for_error(cell, cell_index, exec_reply)
  File "/home/murraybj/CHE498/pyomo_jupyter_book/.venv/lib/python3.10/site-packages/nbclient/client.py", line 918, in _check_raise_for_error
    raise CellExecutionError.from_cell_and_msg(cell, exec_reply_content)
nbclient.exceptions.CellExecutionError: An error occurred while executing the following cell:
------------------
# Warehouse location determination problem using decorator notation
import pyomo.environ as pyo

model = pyo.ConcreteModel(name="(WL)")

W = ['Harlingen', 'Memphis', 'Ashland']
C = ['NYC', 'LA', 'Chicago', 'Houston']
d = {('Harlingen', 'NYC'): 1956, \
     ('Harlingen', 'LA'): 1606, \
     ('Harlingen', 'Chicago'): 1410, \
     ('Harlingen', 'Houston'): 330, \
     ('Memphis', 'NYC'): 1096, \
     ('Memphis', 'LA'): 1792, \
     ('Memphis', 'Chicago'): 531, \
     ('Memphis', 'Houston'): 567, \
     ('Ashland', 'NYC'): 485, \
     ('Ashland', 'LA'): 2322, \
     ('Ashland', 'Chicago'): 324, \
     ('Ashland', 'Houston'): 1236 }
P = 2

model.x = pyo.Var(W, C, bounds=(0,1))
model.y = pyo.Var(W, within=pyo.Binary)

@model.Objective()
def obj(m):
    return sum(d[w,c]*m.x[w,c] for w in W for c in C)

@model.Constraint(C)
def one_per_cust(m, c):
    return sum(m.x[w,c] for w in W) == 1

@model.Constraint(W,C)
def warehouse_active(m, w, c):
    return m.x[w,c] <= m.y[w]

@model.Constraint()
def num_warehouses(m):
    return sum(m.y[w] for w in W) <= P

pyo.SolverFactory('glpk').solve(model)

model.y.pprint()
model.x.pprint()
------------------

----- stdout -----
WARNING: Could not locate the 'glpsol' executable, which is required for
solver 'glpk'
------------------

[0;31m---------------------------------------------------------------------------[0m
[0;31mApplicationError[0m                          Traceback (most recent call last)
Cell [0;32mIn[1], line 41[0m
[1;32m     37[0m [38;5;129m@model[39m[38;5;241m.[39mConstraint()
[1;32m     38[0m [38;5;28;01mdef[39;00m [38;5;21mnum_warehouses[39m(m):
[1;32m     39[0m     [38;5;28;01mreturn[39;00m [38;5;28msum[39m(m[38;5;241m.[39my[w] [38;5;28;01mfor[39;00m w [38;5;129;01min[39;00m W) [38;5;241m<[39m[38;5;241m=[39m P
[0;32m---> 41[0m [43mpyo[49m[38;5;241;43m.[39;49m[43mSolverFactory[49m[43m([49m[38;5;124;43m'[39;49m[38;5;124;43mglpk[39;49m[38;5;124;43m'[39;49m[43m)[49m[38;5;241;43m.[39;49m[43msolve[49m[43m([49m[43mmodel[49m[43m)[49m
[1;32m     43[0m model[38;5;241m.[39my[38;5;241m.[39mpprint()
[1;32m     44[0m model[38;5;241m.[39mx[38;5;241m.[39mpprint()

File [0;32m~/CHE498/pyomo_jupyter_book/.venv/lib/python3.10/site-packages/pyomo/opt/base/solvers.py:534[0m, in [0;36mOptSolver.solve[0;34m(self, *args, **kwds)[0m
[1;32m    531[0m [38;5;28;01mdef[39;00m [38;5;21msolve[39m([38;5;28mself[39m, [38;5;241m*[39margs, [38;5;241m*[39m[38;5;241m*[39mkwds):
[1;32m    532[0m [38;5;250m    [39m[38;5;124;03m"""Solve the problem"""[39;00m
[0;32m--> 534[0m     [38;5;28;43mself[39;49m[38;5;241;43m.[39;49m[43mavailable[49m[43m([49m[43mexception_flag[49m[38;5;241;43m=[39;49m[38;5;28;43;01mTrue[39;49;00m[43m)[49m
[1;32m    535[0m     [38;5;66;03m#[39;00m
[1;32m    536[0m     [38;5;66;03m# If the inputs are models, then validate that they have been[39;00m
[1;32m    537[0m     [38;5;66;03m# constructed! Collect suffix names to try and import from solution.[39;00m
[1;32m    538[0m     [38;5;66;03m#[39;00m
[1;32m    539[0m     [38;5;28;01mfrom[39;00m [38;5;21;01mpyomo[39;00m[38;5;21;01m.[39;00m[38;5;21;01mcore[39;00m[38;5;21;01m.[39;00m[38;5;21;01mbase[39;00m[38;5;21;01m.[39;00m[38;5;21;01mblock[39;00m [38;5;28;01mimport[39;00m BlockData

File [0;32m~/CHE498/pyomo_jupyter_book/.venv/lib/python3.10/site-packages/pyomo/opt/solver/shellcmd.py:140[0m, in [0;36mSystemCallSolver.available[0;34m(self, exception_flag)[0m
[1;32m    138[0m     [38;5;28;01mif[39;00m exception_flag:
[1;32m    139[0m         msg [38;5;241m=[39m [38;5;124m"[39m[38;5;124mNo executable found for solver [39m[38;5;124m'[39m[38;5;132;01m%s[39;00m[38;5;124m'[39m[38;5;124m"[39m
[0;32m--> 140[0m         [38;5;28;01mraise[39;00m ApplicationError(msg [38;5;241m%[39m [38;5;28mself[39m[38;5;241m.[39mname)
[1;32m    141[0m     [38;5;28;01mreturn[39;00m [38;5;28;01mFalse[39;00m
[1;32m    142[0m [38;5;28;01mreturn[39;00m [38;5;28;01mTrue[39;00m

[0;31mApplicationError[0m: No executable found for solver 'glpk'

