Traceback (most recent call last):
  File "c:\Users\bmurr\CHE 498\.venv\Lib\site-packages\jupyter_cache\executors\utils.py", line 58, in single_nb_execution
    executenb(
  File "c:\Users\bmurr\CHE 498\.venv\Lib\site-packages\nbclient\client.py", line 1314, in execute
    return NotebookClient(nb=nb, resources=resources, km=km, **kwargs).execute()
           ^^^^^^^^^^^^^^^^^^^^^^^^^^^^^^^^^^^^^^^^^^^^^^^^^^^^^^^^^^^^^^^^^^^^^
  File "c:\Users\bmurr\CHE 498\.venv\Lib\site-packages\jupyter_core\utils\__init__.py", line 165, in wrapped
    return loop.run_until_complete(inner)
           ^^^^^^^^^^^^^^^^^^^^^^^^^^^^^^
  File "C:\Users\bmurr\AppData\Local\Programs\Python\Python311\Lib\asyncio\base_events.py", line 653, in run_until_complete
    return future.result()
           ^^^^^^^^^^^^^^^
  File "c:\Users\bmurr\CHE 498\.venv\Lib\site-packages\nbclient\client.py", line 709, in async_execute
    await self.async_execute_cell(
  File "c:\Users\bmurr\CHE 498\.venv\Lib\site-packages\nbclient\client.py", line 1062, in async_execute_cell
    await self._check_raise_for_error(cell, cell_index, exec_reply)
  File "c:\Users\bmurr\CHE 498\.venv\Lib\site-packages\nbclient\client.py", line 918, in _check_raise_for_error
    raise CellExecutionError.from_cell_and_msg(cell, exec_reply_content)
nbclient.exceptions.CellExecutionError: An error occurred while executing the following cell:
------------------
import pandas as pd
import pyomo.environ as pyo

df_items = pd.read_excel('knapsack_data.xlsx', sheet_name='data', header=0, index_col=0)
W_max = 14

A = df_items.index.tolist()
b = df_items['Benefit'].to_dict()
w = df_items['Weight'].to_dict()

model = pyo.ConcreteModel()
model.x = pyo.Var( A, within=pyo.Binary )

model.obj = pyo.Objective(
    expr = sum( b[i]*model.x[i] for i in A ), 
    sense = pyo.maximize )

model.weight_con = pyo.Constraint(
    expr = sum( w[i]*model.x[i] for i in A ) <= W_max )

opt = pyo.SolverFactory('glpk')
opt_success = opt.solve(model)

total_weight = sum( w[i]*pyo.value(model.x[i]) for i in A )
print('Total Weight:', total_weight)
print('Total Benefit:', pyo.value(model.obj))

print('%12s %12s' % ('Item', 'Selected'))
print('=========================')
for i in A:
    acquired = 'No'
    if pyo.value(model.x[i]) >= 0.5:
        acquired = 'Yes'
    print('%12s %12s' % (i, acquired))
print('-------------------------')

------------------


[1;31m---------------------------------------------------------------------------[0m
[1;31mModuleNotFoundError[0m                       Traceback (most recent call last)
Cell [1;32mIn[1], line 1[0m
[1;32m----> 1[0m [38;5;28;01mimport[39;00m [38;5;21;01mpandas[39;00m [38;5;28;01mas[39;00m [38;5;21;01mpd[39;00m
[0;32m      2[0m [38;5;28;01mimport[39;00m [38;5;21;01mpyomo[39;00m[38;5;21;01m.[39;00m[38;5;21;01menviron[39;00m [38;5;28;01mas[39;00m [38;5;21;01mpyo[39;00m
[0;32m      4[0m df_items [38;5;241m=[39m pd[38;5;241m.[39mread_excel([38;5;124m'[39m[38;5;124mknapsack_data.xlsx[39m[38;5;124m'[39m, sheet_name[38;5;241m=[39m[38;5;124m'[39m[38;5;124mdata[39m[38;5;124m'[39m, header[38;5;241m=[39m[38;5;241m0[39m, index_col[38;5;241m=[39m[38;5;241m0[39m)

[1;31mModuleNotFoundError[0m: No module named 'pandas'

