Traceback (most recent call last):
  File "c:\Users\bmurr\CHE 498\pyomo_jupyter_book\.venv\Lib\site-packages\jupyter_cache\executors\utils.py", line 58, in single_nb_execution
    executenb(
  File "c:\Users\bmurr\CHE 498\pyomo_jupyter_book\.venv\Lib\site-packages\nbclient\client.py", line 1314, in execute
    return NotebookClient(nb=nb, resources=resources, km=km, **kwargs).execute()
           ^^^^^^^^^^^^^^^^^^^^^^^^^^^^^^^^^^^^^^^^^^^^^^^^^^^^^^^^^^^^^^^^^^^^^
  File "c:\Users\bmurr\CHE 498\pyomo_jupyter_book\.venv\Lib\site-packages\jupyter_core\utils\__init__.py", line 165, in wrapped
    return loop.run_until_complete(inner)
           ^^^^^^^^^^^^^^^^^^^^^^^^^^^^^^
  File "C:\Users\bmurr\AppData\Local\Programs\Python\Python311\Lib\asyncio\base_events.py", line 653, in run_until_complete
    return future.result()
           ^^^^^^^^^^^^^^^
  File "c:\Users\bmurr\CHE 498\pyomo_jupyter_book\.venv\Lib\site-packages\nbclient\client.py", line 709, in async_execute
    await self.async_execute_cell(
  File "c:\Users\bmurr\CHE 498\pyomo_jupyter_book\.venv\Lib\site-packages\nbclient\client.py", line 1062, in async_execute_cell
    await self._check_raise_for_error(cell, cell_index, exec_reply)
  File "c:\Users\bmurr\CHE 498\pyomo_jupyter_book\.venv\Lib\site-packages\nbclient\client.py", line 918, in _check_raise_for_error
    raise CellExecutionError.from_cell_and_msg(cell, exec_reply_content)
nbclient.exceptions.CellExecutionError: An error occurred while executing the following cell:
------------------
import pyomo.environ as pyo
import os
os.environ['PATH'] += ':solvers'
A = ['hammer', 'wrench', 'screwdriver', 'towel']
b = {'hammer':8, 'wrench':3, 'screwdriver':6, 'towel':11}
w = {'hammer':5, 'wrench':7, 'screwdriver':4, 'towel':3}
W_max = 14

model = pyo.ConcreteModel()
model.x = pyo.Var( A, within=pyo.Binary )

model.obj = pyo.Objective(
    expr = sum( b[i]*model.x[i] for i in A ), 
    sense = pyo.maximize )

model.weight_con = pyo.Constraint(
    expr = sum( w[i]*model.x[i] for i in A ) <= W_max )
ipopt_runner_path = "/home/runner/work/pyomo_jupyter_book/pyomo_jupyter_book/solvers/ipopt"
opt = pyo.SolverFactory('ipopt', executable=ipopt_runner_path)
opt_success = opt.solve(model)

model.pprint()


------------------


[1;31m---------------------------------------------------------------------------[0m
[1;31mModuleNotFoundError[0m                       Traceback (most recent call last)
Cell [1;32mIn[1], line 1[0m
[1;32m----> 1[0m [38;5;28;01mimport[39;00m [38;5;21;01mpyomo[39;00m[38;5;21;01m.[39;00m[38;5;21;01menviron[39;00m [38;5;28;01mas[39;00m [38;5;21;01mpyo[39;00m
[0;32m      2[0m [38;5;28;01mimport[39;00m [38;5;21;01mos[39;00m
[0;32m      3[0m os[38;5;241m.[39menviron[[38;5;124m'[39m[38;5;124mPATH[39m[38;5;124m'[39m] [38;5;241m+[39m[38;5;241m=[39m [38;5;124m'[39m[38;5;124m:solvers[39m[38;5;124m'[39m

[1;31mModuleNotFoundError[0m: No module named 'pyomo'

