Traceback (most recent call last):
  File "c:\Users\bmurr\CHE 498\.venv\Lib\site-packages\jupyter_cache\executors\utils.py", line 58, in single_nb_execution
    executenb(
  File "c:\Users\bmurr\CHE 498\.venv\Lib\site-packages\nbclient\client.py", line 1314, in execute
    return NotebookClient(nb=nb, resources=resources, km=km, **kwargs).execute()
           ^^^^^^^^^^^^^^^^^^^^^^^^^^^^^^^^^^^^^^^^^^^^^^^^^^^^^^^^^^^^^^^^^^^^^
  File "c:\Users\bmurr\CHE 498\.venv\Lib\site-packages\jupyter_core\utils\__init__.py", line 165, in wrapped
    return loop.run_until_complete(inner)
           ^^^^^^^^^^^^^^^^^^^^^^^^^^^^^^
  File "C:\Users\bmurr\AppData\Local\Programs\Python\Python311\Lib\asyncio\base_events.py", line 653, in run_until_complete
    return future.result()
           ^^^^^^^^^^^^^^^
  File "c:\Users\bmurr\CHE 498\.venv\Lib\site-packages\nbclient\client.py", line 709, in async_execute
    await self.async_execute_cell(
  File "c:\Users\bmurr\CHE 498\.venv\Lib\site-packages\nbclient\client.py", line 1062, in async_execute_cell
    await self._check_raise_for_error(cell, cell_index, exec_reply)
  File "c:\Users\bmurr\CHE 498\.venv\Lib\site-packages\nbclient\client.py", line 918, in _check_raise_for_error
    raise CellExecutionError.from_cell_and_msg(cell, exec_reply_content)
nbclient.exceptions.CellExecutionError: An error occurred while executing the following cell:
------------------
import pyomo.environ as pyo

model = pyo.ConcreteModel()
model.T = pyo.RangeSet(5)    # time periods

i0 = 5.0           # initial inventory
c = 4.6            # setup cost
h_pos = 0.7        # inventory holding cost
h_neg = 1.2        # shortage cost
P = 5.0            # maximum production amount

# demand during period t
d = {1: 5.0, 2:7.0, 3:6.2, 4:3.1, 5:1.7}

# define the variables
model.y = pyo.Var(model.T, domain=pyo.Binary)
model.x = pyo.Var(model.T, domain=pyo.NonNegativeReals)
model.i = pyo.Var(model.T)
model.i_pos = pyo.Var(model.T, domain=pyo.NonNegativeReals)
model.i_neg = pyo.Var(model.T, domain=pyo.NonNegativeReals)

# define the inventory relationships
def inventory_rule(m, t):
    if t == m.T.first():
        return m.i[t] == i0 + m.x[t] - d[t]
    return m.i[t] == m.i[t-1] + m.x[t] - d[t]
model.inventory = pyo.Constraint(model.T, rule=inventory_rule)

def pos_neg_rule(m, t):
    return m.i[t] == m.i_pos[t] - m.i_neg[t]
model.pos_neg = pyo.Constraint(model.T, rule=pos_neg_rule)

# create the big-M constraint for the production indicator variable
def prod_indicator_rule(m,t):
    return m.x[t] <= P*m.y[t]
model.prod_indicator = pyo.Constraint(model.T, rule=prod_indicator_rule)

# define the cost function
def obj_rule(m):
    return sum(c*m.y[t] + h_pos*m.i_pos[t] + h_neg*m.i_neg[t] for t in m.T)
model.obj = pyo.Objective(rule=obj_rule)

# solve the problem
solver = pyo.SolverFactory('glpk')
solver.solve(model)

# print the results
for t in model.T:
    print('Period: {0}, Prod. Amount: {1}'.format(t, pyo.value(model.x[t]))) 

------------------

----- stdout -----
WARNING: Could not locate the 'glpsol' executable, which is required for
solver 'glpk'
------------------

[1;31m---------------------------------------------------------------------------[0m
[1;31mApplicationError[0m                          Traceback (most recent call last)
Cell [1;32mIn[1], line 45[0m
[0;32m     43[0m [38;5;66;03m# solve the problem[39;00m
[0;32m     44[0m solver [38;5;241m=[39m pyo[38;5;241m.[39mSolverFactory([38;5;124m'[39m[38;5;124mglpk[39m[38;5;124m'[39m)
[1;32m---> 45[0m [43msolver[49m[38;5;241;43m.[39;49m[43msolve[49m[43m([49m[43mmodel[49m[43m)[49m
[0;32m     47[0m [38;5;66;03m# print the results[39;00m
[0;32m     48[0m [38;5;28;01mfor[39;00m t [38;5;129;01min[39;00m model[38;5;241m.[39mT:

File [1;32mc:\Users\bmurr\CHE 498\.venv\Lib\site-packages\pyomo\opt\base\solvers.py:534[0m, in [0;36mOptSolver.solve[1;34m(self, *args, **kwds)[0m
[0;32m    531[0m [38;5;28;01mdef[39;00m [38;5;21msolve[39m([38;5;28mself[39m, [38;5;241m*[39margs, [38;5;241m*[39m[38;5;241m*[39mkwds):
[0;32m    532[0m [38;5;250m    [39m[38;5;124;03m"""Solve the problem"""[39;00m
[1;32m--> 534[0m     [38;5;28;43mself[39;49m[38;5;241;43m.[39;49m[43mavailable[49m[43m([49m[43mexception_flag[49m[38;5;241;43m=[39;49m[38;5;28;43;01mTrue[39;49;00m[43m)[49m
[0;32m    535[0m     [38;5;66;03m#[39;00m
[0;32m    536[0m     [38;5;66;03m# If the inputs are models, then validate that they have been[39;00m
[0;32m    537[0m     [38;5;66;03m# constructed! Collect suffix names to try and import from solution.[39;00m
[0;32m    538[0m     [38;5;66;03m#[39;00m
[0;32m    539[0m     [38;5;28;01mfrom[39;00m [38;5;21;01mpyomo[39;00m[38;5;21;01m.[39;00m[38;5;21;01mcore[39;00m[38;5;21;01m.[39;00m[38;5;21;01mbase[39;00m[38;5;21;01m.[39;00m[38;5;21;01mblock[39;00m [38;5;28;01mimport[39;00m BlockData

File [1;32mc:\Users\bmurr\CHE 498\.venv\Lib\site-packages\pyomo\opt\solver\shellcmd.py:140[0m, in [0;36mSystemCallSolver.available[1;34m(self, exception_flag)[0m
[0;32m    138[0m     [38;5;28;01mif[39;00m exception_flag:
[0;32m    139[0m         msg [38;5;241m=[39m [38;5;124m"[39m[38;5;124mNo executable found for solver [39m[38;5;124m'[39m[38;5;132;01m%s[39;00m[38;5;124m'[39m[38;5;124m"[39m
[1;32m--> 140[0m         [38;5;28;01mraise[39;00m ApplicationError(msg [38;5;241m%[39m [38;5;28mself[39m[38;5;241m.[39mname)
[0;32m    141[0m     [38;5;28;01mreturn[39;00m [38;5;28;01mFalse[39;00m
[0;32m    142[0m [38;5;28;01mreturn[39;00m [38;5;28;01mTrue[39;00m

[1;31mApplicationError[0m: No executable found for solver 'glpk'

