Traceback (most recent call last):
  File "c:\Users\bmurr\CHE 498\pyomo_jupyter_book\.venv\Lib\site-packages\jupyter_cache\executors\utils.py", line 58, in single_nb_execution
    executenb(
  File "c:\Users\bmurr\CHE 498\pyomo_jupyter_book\.venv\Lib\site-packages\nbclient\client.py", line 1314, in execute
    return NotebookClient(nb=nb, resources=resources, km=km, **kwargs).execute()
           ^^^^^^^^^^^^^^^^^^^^^^^^^^^^^^^^^^^^^^^^^^^^^^^^^^^^^^^^^^^^^^^^^^^^^
  File "c:\Users\bmurr\CHE 498\pyomo_jupyter_book\.venv\Lib\site-packages\jupyter_core\utils\__init__.py", line 165, in wrapped
    return loop.run_until_complete(inner)
           ^^^^^^^^^^^^^^^^^^^^^^^^^^^^^^
  File "C:\Users\bmurr\AppData\Local\Programs\Python\Python311\Lib\asyncio\base_events.py", line 653, in run_until_complete
    return future.result()
           ^^^^^^^^^^^^^^^
  File "c:\Users\bmurr\CHE 498\pyomo_jupyter_book\.venv\Lib\site-packages\nbclient\client.py", line 709, in async_execute
    await self.async_execute_cell(
  File "c:\Users\bmurr\CHE 498\pyomo_jupyter_book\.venv\Lib\site-packages\nbclient\client.py", line 1062, in async_execute_cell
    await self._check_raise_for_error(cell, cell_index, exec_reply)
  File "c:\Users\bmurr\CHE 498\pyomo_jupyter_book\.venv\Lib\site-packages\nbclient\client.py", line 918, in _check_raise_for_error
    raise CellExecutionError.from_cell_and_msg(cell, exec_reply_content)
nbclient.exceptions.CellExecutionError: An error occurred while executing the following cell:
------------------
# rosenbrock_script_loop.py: A Pyomo model for the Rosenbrock problem
import pyomo.environ as pyo

model = pyo.ConcreteModel()
model.x = pyo.Var()
model.y = pyo.Var()

def rosenbrock(m):
    return (1.0-m.x)**2 + 100.0*(m.y - m.x**2)**2
model.obj = pyo.Objective(rule=rosenbrock, sense=pyo.minimize)


ipopt_runner_path = "/home/runner/work/pyomo_jupyter_book/pyomo_jupyter_book/solvers/ipopt"
solver = pyo.SolverFactory('ipopt', executable=ipopt_runner_path)

print('x_init, y_init, x_soln, y_soln')
y_init = 5.0
for x_init in range(2, 6):
    model.x = x_init
    model.y = 5.0

    solver.solve(model)

    print("{0:6.2f}  {1:6.2f}  {2:6.2f}  {3:6.2f}".format(x_init, \
            y_init, pyo.value(model.x), pyo.value(model.y)))

------------------


[1;31m---------------------------------------------------------------------------[0m
[1;31mModuleNotFoundError[0m                       Traceback (most recent call last)
Cell [1;32mIn[1], line 2[0m
[0;32m      1[0m [38;5;66;03m# rosenbrock_script_loop.py: A Pyomo model for the Rosenbrock problem[39;00m
[1;32m----> 2[0m [38;5;28;01mimport[39;00m [38;5;21;01mpyomo[39;00m[38;5;21;01m.[39;00m[38;5;21;01menviron[39;00m [38;5;28;01mas[39;00m [38;5;21;01mpyo[39;00m
[0;32m      4[0m model [38;5;241m=[39m pyo[38;5;241m.[39mConcreteModel()
[0;32m      5[0m model[38;5;241m.[39mx [38;5;241m=[39m pyo[38;5;241m.[39mVar()

[1;31mModuleNotFoundError[0m: No module named 'pyomo'

