Traceback (most recent call last):
  File "/home/runner/.local/lib/python3.12/site-packages/jupyter_core/utils/__init__.py", line 154, in wrapped
    asyncio.get_running_loop()
RuntimeError: no running event loop

During handling of the above exception, another exception occurred:

Traceback (most recent call last):
  File "/home/runner/.local/lib/python3.12/site-packages/jupyter_cache/executors/utils.py", line 58, in single_nb_execution
    executenb(
  File "/home/runner/.local/lib/python3.12/site-packages/nbclient/client.py", line 1319, in execute
    return NotebookClient(nb=nb, resources=resources, km=km, **kwargs).execute()
           ^^^^^^^^^^^^^^^^^^^^^^^^^^^^^^^^^^^^^^^^^^^^^^^^^^^^^^^^^^^^^^^^^^^^^
  File "/home/runner/.local/lib/python3.12/site-packages/jupyter_core/utils/__init__.py", line 158, in wrapped
    return loop.run_until_complete(inner)
           ^^^^^^^^^^^^^^^^^^^^^^^^^^^^^^
  File "/usr/lib/python3.12/asyncio/base_events.py", line 687, in run_until_complete
    return future.result()
           ^^^^^^^^^^^^^^^
  File "/home/runner/.local/lib/python3.12/site-packages/nbclient/client.py", line 709, in async_execute
    await self.async_execute_cell(
  File "/home/runner/.local/lib/python3.12/site-packages/nbclient/client.py", line 1062, in async_execute_cell
    await self._check_raise_for_error(cell, cell_index, exec_reply)
  File "/home/runner/.local/lib/python3.12/site-packages/nbclient/client.py", line 918, in _check_raise_for_error
    raise CellExecutionError.from_cell_and_msg(cell, exec_reply_content)
nbclient.exceptions.CellExecutionError: An error occurred while executing the following cell:
------------------
# rosenbrock_script_loop.py: A Pyomo model for the Rosenbrock problem
import pyomo.environ as pyo

model = pyo.ConcreteModel()
model.x = pyo.Var()
model.y = pyo.Var()

def rosenbrock(m):
    return (1.0-m.x)**2 + 100.0*(m.y - m.x**2)**2
model.obj = pyo.Objective(rule=rosenbrock, sense=pyo.minimize)


solver = pyo.SolverFactory('ipopt')

print('x_init, y_init, x_soln, y_soln')
y_init = 5.0
for x_init in range(2, 6):
    model.x = x_init
    model.y = 5.0

    solver.solve(model)

    print("{0:6.2f}  {1:6.2f}  {2:6.2f}  {3:6.2f}".format(x_init, \
            y_init, pyo.value(model.x), pyo.value(model.y)))

------------------

----- stdout -----
x_init, y_init, x_soln, y_soln
WARNING: Could not locate the 'ipopt' executable, which is required for solver
ipopt
------------------

[31m---------------------------------------------------------------------------[39m
[31mApplicationError[39m                          Traceback (most recent call last)
[36mCell[39m[36m [39m[32mIn[1][39m[32m, line 21[39m
[32m     18[39m model.x = x_init
[32m     19[39m model.y = [32m5.0[39m
[32m---> [39m[32m21[39m [43msolver[49m[43m.[49m[43msolve[49m[43m([49m[43mmodel[49m[43m)[49m
[32m     23[39m [38;5;28mprint[39m([33m"[39m[38;5;132;01m{0:6.2f}[39;00m[33m  [39m[38;5;132;01m{1:6.2f}[39;00m[33m  [39m[38;5;132;01m{2:6.2f}[39;00m[33m  [39m[38;5;132;01m{3:6.2f}[39;00m[33m"[39m.format(x_init, \
[32m     24[39m         y_init, pyo.value(model.x), pyo.value(model.y)))

[36mFile [39m[32m~/.local/lib/python3.12/site-packages/pyomo/opt/base/solvers.py:534[39m, in [36mOptSolver.solve[39m[34m(self, *args, **kwds)[39m
[32m    531[39m [38;5;28;01mdef[39;00m [34msolve[39m([38;5;28mself[39m, *args, **kwds):
[32m    532[39m [38;5;250m    [39m[33;03m"""Solve the problem"""[39;00m
[32m--> [39m[32m534[39m     [38;5;28;43mself[39;49m[43m.[49m[43mavailable[49m[43m([49m[43mexception_flag[49m[43m=[49m[38;5;28;43;01mTrue[39;49;00m[43m)[49m
[32m    535[39m     [38;5;66;03m#[39;00m
[32m    536[39m     [38;5;66;03m# If the inputs are models, then validate that they have been[39;00m
[32m    537[39m     [38;5;66;03m# constructed! Collect suffix names to try and import from solution.[39;00m
[32m    538[39m     [38;5;66;03m#[39;00m
[32m    539[39m     [38;5;28;01mfrom[39;00m [34;01mpyomo[39;00m[34;01m.[39;00m[34;01mcore[39;00m[34;01m.[39;00m[34;01mbase[39;00m[34;01m.[39;00m[34;01mblock[39;00m [38;5;28;01mimport[39;00m BlockData

[36mFile [39m[32m~/.local/lib/python3.12/site-packages/pyomo/opt/solver/shellcmd.py:140[39m, in [36mSystemCallSolver.available[39m[34m(self, exception_flag)[39m
[32m    138[39m     [38;5;28;01mif[39;00m exception_flag:
[32m    139[39m         msg = [33m"[39m[33mNo executable found for solver [39m[33m'[39m[38;5;132;01m%s[39;00m[33m'[39m[33m"[39m
[32m--> [39m[32m140[39m         [38;5;28;01mraise[39;00m ApplicationError(msg % [38;5;28mself[39m.name)
[32m    141[39m     [38;5;28;01mreturn[39;00m [38;5;28;01mFalse[39;00m
[32m    142[39m [38;5;28;01mreturn[39;00m [38;5;28;01mTrue[39;00m

[31mApplicationError[39m: No executable found for solver 'ipopt'

