Traceback (most recent call last):
  File "c:\Users\bmurr\CHE 498\pyomo_jupyter_book\.venv\Lib\site-packages\jupyter_cache\executors\utils.py", line 58, in single_nb_execution
    executenb(
  File "c:\Users\bmurr\CHE 498\pyomo_jupyter_book\.venv\Lib\site-packages\nbclient\client.py", line 1314, in execute
    return NotebookClient(nb=nb, resources=resources, km=km, **kwargs).execute()
           ^^^^^^^^^^^^^^^^^^^^^^^^^^^^^^^^^^^^^^^^^^^^^^^^^^^^^^^^^^^^^^^^^^^^^
  File "c:\Users\bmurr\CHE 498\pyomo_jupyter_book\.venv\Lib\site-packages\jupyter_core\utils\__init__.py", line 165, in wrapped
    return loop.run_until_complete(inner)
           ^^^^^^^^^^^^^^^^^^^^^^^^^^^^^^
  File "C:\Users\bmurr\AppData\Local\Programs\Python\Python311\Lib\asyncio\base_events.py", line 653, in run_until_complete
    return future.result()
           ^^^^^^^^^^^^^^^
  File "c:\Users\bmurr\CHE 498\pyomo_jupyter_book\.venv\Lib\site-packages\nbclient\client.py", line 709, in async_execute
    await self.async_execute_cell(
  File "c:\Users\bmurr\CHE 498\pyomo_jupyter_book\.venv\Lib\site-packages\nbclient\client.py", line 1062, in async_execute_cell
    await self._check_raise_for_error(cell, cell_index, exec_reply)
  File "c:\Users\bmurr\CHE 498\pyomo_jupyter_book\.venv\Lib\site-packages\nbclient\client.py", line 918, in _check_raise_for_error
    raise CellExecutionError.from_cell_and_msg(cell, exec_reply_content)
nbclient.exceptions.CellExecutionError: An error occurred while executing the following cell:
------------------
import pyomo.environ as pyo

model = pyo.ConcreteModel()

model.x = pyo.Var(initialize=5.0)
model.y = pyo.Var(initialize=5.0)

def obj_rule(m):
    return (m.x-1.01)**2 + m.y**2
model.obj = pyo.Objective(rule=obj_rule)

def con_rule(m):
    return m.y == pyo.sqrt(m.x - 1.0)
model.con = pyo.Constraint(rule=con_rule)

ipopt_runner_path = "/home/runner/work/pyomo_jupyter_book/pyomo_jupyter_book/solvers/ipopt"
solver = pyo.SolverFactory('ipopt', executable=ipopt_runner_path)
solver.options['halt_on_ampl_error'] = 'yes'
solver.solve(model, tee=True)

print(pyo.value(model.x))
print(pyo.value(model.y))
------------------


[1;31m---------------------------------------------------------------------------[0m
[1;31mModuleNotFoundError[0m                       Traceback (most recent call last)
Cell [1;32mIn[1], line 1[0m
[1;32m----> 1[0m [38;5;28;01mimport[39;00m [38;5;21;01mpyomo[39;00m[38;5;21;01m.[39;00m[38;5;21;01menviron[39;00m [38;5;28;01mas[39;00m [38;5;21;01mpyo[39;00m
[0;32m      3[0m model [38;5;241m=[39m pyo[38;5;241m.[39mConcreteModel()
[0;32m      5[0m model[38;5;241m.[39mx [38;5;241m=[39m pyo[38;5;241m.[39mVar(initialize[38;5;241m=[39m[38;5;241m5.0[39m)

[1;31mModuleNotFoundError[0m: No module named 'pyomo'

