Traceback (most recent call last):
  File "c:\Users\bmurr\CHE 498\.venv\Lib\site-packages\jupyter_cache\executors\utils.py", line 58, in single_nb_execution
    executenb(
  File "c:\Users\bmurr\CHE 498\.venv\Lib\site-packages\nbclient\client.py", line 1314, in execute
    return NotebookClient(nb=nb, resources=resources, km=km, **kwargs).execute()
           ^^^^^^^^^^^^^^^^^^^^^^^^^^^^^^^^^^^^^^^^^^^^^^^^^^^^^^^^^^^^^^^^^^^^^
  File "c:\Users\bmurr\CHE 498\.venv\Lib\site-packages\jupyter_core\utils\__init__.py", line 165, in wrapped
    return loop.run_until_complete(inner)
           ^^^^^^^^^^^^^^^^^^^^^^^^^^^^^^
  File "C:\Users\bmurr\AppData\Local\Programs\Python\Python311\Lib\asyncio\base_events.py", line 653, in run_until_complete
    return future.result()
           ^^^^^^^^^^^^^^^
  File "c:\Users\bmurr\CHE 498\.venv\Lib\site-packages\nbclient\client.py", line 709, in async_execute
    await self.async_execute_cell(
  File "c:\Users\bmurr\CHE 498\.venv\Lib\site-packages\nbclient\client.py", line 1062, in async_execute_cell
    await self._check_raise_for_error(cell, cell_index, exec_reply)
  File "c:\Users\bmurr\CHE 498\.venv\Lib\site-packages\nbclient\client.py", line 918, in _check_raise_for_error
    raise CellExecutionError.from_cell_and_msg(cell, exec_reply_content)
nbclient.exceptions.CellExecutionError: An error occurred while executing the following cell:
------------------
import pyomo.environ as pyo

model = pyo.ConcreteModel()

model.x = pyo.Var(initialize=5.0)
model.y = pyo.Var(initialize=5.0)

def obj_rule(m):
    return (m.x-1.01)**2 + m.y**2
model.obj = pyo.Objective(rule=obj_rule)

def con_rule(m):
    return (m.x - 1.0) / m.y == 1.0
model.con = pyo.Constraint(rule=con_rule)

solver = pyo.SolverFactory('ipopt')
solver.solve(model, tee=True)

print(pyo.value(model.x))
print(pyo.value(model.y))
------------------

----- stdout -----
WARNING: Could not locate the 'ipopt' executable, which is required for solver
ipopt
------------------

[1;31m---------------------------------------------------------------------------[0m
[1;31mApplicationError[0m                          Traceback (most recent call last)
Cell [1;32mIn[1], line 17[0m
[0;32m     14[0m model[38;5;241m.[39mcon [38;5;241m=[39m pyo[38;5;241m.[39mConstraint(rule[38;5;241m=[39mcon_rule)
[0;32m     16[0m solver [38;5;241m=[39m pyo[38;5;241m.[39mSolverFactory([38;5;124m'[39m[38;5;124mipopt[39m[38;5;124m'[39m)
[1;32m---> 17[0m [43msolver[49m[38;5;241;43m.[39;49m[43msolve[49m[43m([49m[43mmodel[49m[43m,[49m[43m [49m[43mtee[49m[38;5;241;43m=[39;49m[38;5;28;43;01mTrue[39;49;00m[43m)[49m
[0;32m     19[0m [38;5;28mprint[39m(pyo[38;5;241m.[39mvalue(model[38;5;241m.[39mx))
[0;32m     20[0m [38;5;28mprint[39m(pyo[38;5;241m.[39mvalue(model[38;5;241m.[39my))

File [1;32mc:\Users\bmurr\CHE 498\.venv\Lib\site-packages\pyomo\opt\base\solvers.py:534[0m, in [0;36mOptSolver.solve[1;34m(self, *args, **kwds)[0m
[0;32m    531[0m [38;5;28;01mdef[39;00m [38;5;21msolve[39m([38;5;28mself[39m, [38;5;241m*[39margs, [38;5;241m*[39m[38;5;241m*[39mkwds):
[0;32m    532[0m [38;5;250m    [39m[38;5;124;03m"""Solve the problem"""[39;00m
[1;32m--> 534[0m     [38;5;28;43mself[39;49m[38;5;241;43m.[39;49m[43mavailable[49m[43m([49m[43mexception_flag[49m[38;5;241;43m=[39;49m[38;5;28;43;01mTrue[39;49;00m[43m)[49m
[0;32m    535[0m     [38;5;66;03m#[39;00m
[0;32m    536[0m     [38;5;66;03m# If the inputs are models, then validate that they have been[39;00m
[0;32m    537[0m     [38;5;66;03m# constructed! Collect suffix names to try and import from solution.[39;00m
[0;32m    538[0m     [38;5;66;03m#[39;00m
[0;32m    539[0m     [38;5;28;01mfrom[39;00m [38;5;21;01mpyomo[39;00m[38;5;21;01m.[39;00m[38;5;21;01mcore[39;00m[38;5;21;01m.[39;00m[38;5;21;01mbase[39;00m[38;5;21;01m.[39;00m[38;5;21;01mblock[39;00m [38;5;28;01mimport[39;00m BlockData

File [1;32mc:\Users\bmurr\CHE 498\.venv\Lib\site-packages\pyomo\opt\solver\shellcmd.py:140[0m, in [0;36mSystemCallSolver.available[1;34m(self, exception_flag)[0m
[0;32m    138[0m     [38;5;28;01mif[39;00m exception_flag:
[0;32m    139[0m         msg [38;5;241m=[39m [38;5;124m"[39m[38;5;124mNo executable found for solver [39m[38;5;124m'[39m[38;5;132;01m%s[39;00m[38;5;124m'[39m[38;5;124m"[39m
[1;32m--> 140[0m         [38;5;28;01mraise[39;00m ApplicationError(msg [38;5;241m%[39m [38;5;28mself[39m[38;5;241m.[39mname)
[0;32m    141[0m     [38;5;28;01mreturn[39;00m [38;5;28;01mFalse[39;00m
[0;32m    142[0m [38;5;28;01mreturn[39;00m [38;5;28;01mTrue[39;00m

[1;31mApplicationError[0m: No executable found for solver 'ipopt'

