Traceback (most recent call last):
  File "c:\Users\bmurr\CHE 498\.venv\Lib\site-packages\jupyter_cache\executors\utils.py", line 58, in single_nb_execution
    executenb(
  File "c:\Users\bmurr\CHE 498\.venv\Lib\site-packages\nbclient\client.py", line 1314, in execute
    return NotebookClient(nb=nb, resources=resources, km=km, **kwargs).execute()
           ^^^^^^^^^^^^^^^^^^^^^^^^^^^^^^^^^^^^^^^^^^^^^^^^^^^^^^^^^^^^^^^^^^^^^
  File "c:\Users\bmurr\CHE 498\.venv\Lib\site-packages\jupyter_core\utils\__init__.py", line 165, in wrapped
    return loop.run_until_complete(inner)
           ^^^^^^^^^^^^^^^^^^^^^^^^^^^^^^
  File "C:\Users\bmurr\AppData\Local\Programs\Python\Python311\Lib\asyncio\base_events.py", line 653, in run_until_complete
    return future.result()
           ^^^^^^^^^^^^^^^
  File "c:\Users\bmurr\CHE 498\.venv\Lib\site-packages\nbclient\client.py", line 709, in async_execute
    await self.async_execute_cell(
  File "c:\Users\bmurr\CHE 498\.venv\Lib\site-packages\nbclient\client.py", line 1062, in async_execute_cell
    await self._check_raise_for_error(cell, cell_index, exec_reply)
  File "c:\Users\bmurr\CHE 498\.venv\Lib\site-packages\nbclient\client.py", line 918, in _check_raise_for_error
    raise CellExecutionError.from_cell_and_msg(cell, exec_reply_content)
nbclient.exceptions.CellExecutionError: An error occurred while executing the following cell:
------------------
import pyomo.environ as pyo

# create the concrete model
model = pyo.ConcreteModel()

# set the data (native python data)
k1 = 5.0/6.0     # min^-1
k2 = 5.0/3.0     # min^-1
k3 = 1.0/6000.0  # m^3/(gmol min)
caf = 10000.0    # gmol/m^3

# create the variables
model.sv = pyo.Var(initialize = 1.0, within=pyo.PositiveReals)
model.ca = pyo.Var(initialize = 5000.0, within=pyo.PositiveReals)
model.cb = pyo.Var(initialize = 2000.0, within=pyo.PositiveReals)
model.cc = pyo.Var(initialize = 2000.0, within=pyo.PositiveReals)
model.cd = pyo.Var(initialize = 1000.0, within=pyo.PositiveReals)

# create the objective
model.obj = pyo.Objective(expr = model.cb, sense=pyo.maximize)

# create the constraints
model.ca_bal = pyo.Constraint(expr = (0 == model.sv * caf \
                 - model.sv * model.ca - k1 * model.ca \
                 -  2.0 * k3 * model.ca ** 2.0))

model.cb_bal = pyo.Constraint(expr=(0 == -model.sv * model.cb \
                 + k1 * model.ca - k2 * model.cb))

model.cc_bal = pyo.Constraint(expr=(0 == -model.sv * model.cc \
                 + k2 * model.cb))

model.cd_bal = pyo.Constraint(expr=(0 == -model.sv * model.cd \
                 + k3 * model.ca ** 2.0))

pyo.SolverFactory('ipopt').solve(model)
model.pprint()

------------------

----- stdout -----
WARNING: Could not locate the 'ipopt' executable, which is required for solver
ipopt
------------------

[1;31m---------------------------------------------------------------------------[0m
[1;31mApplicationError[0m                          Traceback (most recent call last)
Cell [1;32mIn[1], line 36[0m
[0;32m     30[0m model[38;5;241m.[39mcc_bal [38;5;241m=[39m pyo[38;5;241m.[39mConstraint(expr[38;5;241m=[39m([38;5;241m0[39m [38;5;241m==[39m [38;5;241m-[39mmodel[38;5;241m.[39msv [38;5;241m*[39m model[38;5;241m.[39mcc \
[0;32m     31[0m                  [38;5;241m+[39m k2 [38;5;241m*[39m model[38;5;241m.[39mcb))
[0;32m     33[0m model[38;5;241m.[39mcd_bal [38;5;241m=[39m pyo[38;5;241m.[39mConstraint(expr[38;5;241m=[39m([38;5;241m0[39m [38;5;241m==[39m [38;5;241m-[39mmodel[38;5;241m.[39msv [38;5;241m*[39m model[38;5;241m.[39mcd \
[0;32m     34[0m                  [38;5;241m+[39m k3 [38;5;241m*[39m model[38;5;241m.[39mca [38;5;241m*[39m[38;5;241m*[39m [38;5;241m2.0[39m))
[1;32m---> 36[0m [43mpyo[49m[38;5;241;43m.[39;49m[43mSolverFactory[49m[43m([49m[38;5;124;43m'[39;49m[38;5;124;43mipopt[39;49m[38;5;124;43m'[39;49m[43m)[49m[38;5;241;43m.[39;49m[43msolve[49m[43m([49m[43mmodel[49m[43m)[49m
[0;32m     37[0m model[38;5;241m.[39mpprint()

File [1;32mc:\Users\bmurr\CHE 498\.venv\Lib\site-packages\pyomo\opt\base\solvers.py:534[0m, in [0;36mOptSolver.solve[1;34m(self, *args, **kwds)[0m
[0;32m    531[0m [38;5;28;01mdef[39;00m [38;5;21msolve[39m([38;5;28mself[39m, [38;5;241m*[39margs, [38;5;241m*[39m[38;5;241m*[39mkwds):
[0;32m    532[0m [38;5;250m    [39m[38;5;124;03m"""Solve the problem"""[39;00m
[1;32m--> 534[0m     [38;5;28;43mself[39;49m[38;5;241;43m.[39;49m[43mavailable[49m[43m([49m[43mexception_flag[49m[38;5;241;43m=[39;49m[38;5;28;43;01mTrue[39;49;00m[43m)[49m
[0;32m    535[0m     [38;5;66;03m#[39;00m
[0;32m    536[0m     [38;5;66;03m# If the inputs are models, then validate that they have been[39;00m
[0;32m    537[0m     [38;5;66;03m# constructed! Collect suffix names to try and import from solution.[39;00m
[0;32m    538[0m     [38;5;66;03m#[39;00m
[0;32m    539[0m     [38;5;28;01mfrom[39;00m [38;5;21;01mpyomo[39;00m[38;5;21;01m.[39;00m[38;5;21;01mcore[39;00m[38;5;21;01m.[39;00m[38;5;21;01mbase[39;00m[38;5;21;01m.[39;00m[38;5;21;01mblock[39;00m [38;5;28;01mimport[39;00m BlockData

File [1;32mc:\Users\bmurr\CHE 498\.venv\Lib\site-packages\pyomo\opt\solver\shellcmd.py:140[0m, in [0;36mSystemCallSolver.available[1;34m(self, exception_flag)[0m
[0;32m    138[0m     [38;5;28;01mif[39;00m exception_flag:
[0;32m    139[0m         msg [38;5;241m=[39m [38;5;124m"[39m[38;5;124mNo executable found for solver [39m[38;5;124m'[39m[38;5;132;01m%s[39;00m[38;5;124m'[39m[38;5;124m"[39m
[1;32m--> 140[0m         [38;5;28;01mraise[39;00m ApplicationError(msg [38;5;241m%[39m [38;5;28mself[39m[38;5;241m.[39mname)
[0;32m    141[0m     [38;5;28;01mreturn[39;00m [38;5;28;01mFalse[39;00m
[0;32m    142[0m [38;5;28;01mreturn[39;00m [38;5;28;01mTrue[39;00m

[1;31mApplicationError[0m: No executable found for solver 'ipopt'

