Traceback (most recent call last):
  File "c:\Users\bmurr\CHE 498\pyomo_jupyter_book\.venv\Lib\site-packages\jupyter_cache\executors\utils.py", line 58, in single_nb_execution
    executenb(
  File "c:\Users\bmurr\CHE 498\pyomo_jupyter_book\.venv\Lib\site-packages\nbclient\client.py", line 1314, in execute
    return NotebookClient(nb=nb, resources=resources, km=km, **kwargs).execute()
           ^^^^^^^^^^^^^^^^^^^^^^^^^^^^^^^^^^^^^^^^^^^^^^^^^^^^^^^^^^^^^^^^^^^^^
  File "c:\Users\bmurr\CHE 498\pyomo_jupyter_book\.venv\Lib\site-packages\jupyter_core\utils\__init__.py", line 165, in wrapped
    return loop.run_until_complete(inner)
           ^^^^^^^^^^^^^^^^^^^^^^^^^^^^^^
  File "C:\Users\bmurr\AppData\Local\Programs\Python\Python311\Lib\asyncio\base_events.py", line 653, in run_until_complete
    return future.result()
           ^^^^^^^^^^^^^^^
  File "c:\Users\bmurr\CHE 498\pyomo_jupyter_book\.venv\Lib\site-packages\nbclient\client.py", line 709, in async_execute
    await self.async_execute_cell(
  File "c:\Users\bmurr\CHE 498\pyomo_jupyter_book\.venv\Lib\site-packages\nbclient\client.py", line 1062, in async_execute_cell
    await self._check_raise_for_error(cell, cell_index, exec_reply)
  File "c:\Users\bmurr\CHE 498\pyomo_jupyter_book\.venv\Lib\site-packages\nbclient\client.py", line 918, in _check_raise_for_error
    raise CellExecutionError.from_cell_and_msg(cell, exec_reply_content)
nbclient.exceptions.CellExecutionError: An error occurred while executing the following cell:
------------------
import pyomo.environ as pyo

# create the concrete model
model = pyo.ConcreteModel()

# set the data (native python data)
k1 = 5.0/6.0     # min^-1
k2 = 5.0/3.0     # min^-1
k3 = 1.0/6000.0  # m^3/(gmol min)
caf = 10000.0    # gmol/m^3

# create the variables
model.sv = pyo.Var(initialize = 1.0, within=pyo.PositiveReals)
model.ca = pyo.Var(initialize = 5000.0, within=pyo.PositiveReals)
model.cb = pyo.Var(initialize = 2000.0, within=pyo.PositiveReals)
model.cc = pyo.Var(initialize = 2000.0, within=pyo.PositiveReals)
model.cd = pyo.Var(initialize = 1000.0, within=pyo.PositiveReals)

# create the objective
model.obj = pyo.Objective(expr = model.cb, sense=pyo.maximize)

# create the constraints
model.ca_bal = pyo.Constraint(expr = (0 == model.sv * caf \
                 - model.sv * model.ca - k1 * model.ca \
                 -  2.0 * k3 * model.ca ** 2.0))

model.cb_bal = pyo.Constraint(expr=(0 == -model.sv * model.cb \
                 + k1 * model.ca - k2 * model.cb))

model.cc_bal = pyo.Constraint(expr=(0 == -model.sv * model.cc \
                 + k2 * model.cb))

model.cd_bal = pyo.Constraint(expr=(0 == -model.sv * model.cd \
                 + k3 * model.ca ** 2.0))

ipopt_runner_path = "/home/runner/work/pyomo_jupyter_book/pyomo_jupyter_book/solvers/ipopt"
solver = pyo.SolverFactory('ipopt', executable=ipopt_runner_path)

solver.solve(model)
model.pprint()

------------------


[1;31m---------------------------------------------------------------------------[0m
[1;31mModuleNotFoundError[0m                       Traceback (most recent call last)
Cell [1;32mIn[1], line 1[0m
[1;32m----> 1[0m [38;5;28;01mimport[39;00m [38;5;21;01mpyomo[39;00m[38;5;21;01m.[39;00m[38;5;21;01menviron[39;00m [38;5;28;01mas[39;00m [38;5;21;01mpyo[39;00m
[0;32m      3[0m [38;5;66;03m# create the concrete model[39;00m
[0;32m      4[0m model [38;5;241m=[39m pyo[38;5;241m.[39mConcreteModel()

[1;31mModuleNotFoundError[0m: No module named 'pyomo'

